<?xml version="0.0" ?>
<robot name="ballbot">
	<link name="base_link">
		<inertial>
			<origin rpy="0.00000 -0.00000 0.00000" xyz="0.00288 0.00043 0.26370"/>
			<mass value="4.88335"/>
			<inertia ixx="65715.97620" ixy="0" ixz="0" iyy="62217.73779" iyz="0" izz="38773.58644"/>
		</inertial>
		<collision>
			<origin rpy="0.00000 -0.00000 0.00000" xyz="0.00000 0.00000 0.00000"/>
			<geometry>
				<mesh filename="unknown_file" scale="1.00000 1.00000 1.00000"/>
			</geometry>
		</collision>
	</link>
	<link name="torso_link">
		<inertial>
			<origin rpy="0.00000 -0.00000 0.00000" xyz="-0.00002 -0.00001 0.34937"/>
			<mass value="3.20426"/>
			<inertia ixx="87624.61461" ixy="0" ixz="0" iyy="63505.58719" iyz="0" izz="30595.04917"/>
		</inertial>
		<collision>
			<origin rpy="0.00000 -0.00000 0.00000" xyz="0.00000 0.00000 0.00000"/>
			<geometry>
				<mesh filename="unknown_file" scale="1.00000 1.00000 1.00000"/>
			</geometry>
		</collision>
	</link>
	<link name="link0_3">
		<inertial>
			<origin rpy="0.00000 -0.00000 0.00000" xyz="0.00000 0.00000 0.00000"/>
			<mass value="0.00000"/>
			<inertia ixx="0.00000" ixy="0" ixz="0" iyy="0.00000" iyz="0" izz="0.00000"/>
		</inertial>
	</link>
	<link name="neck_link">
		<inertial>
			<origin rpy="0.00000 -0.00000 0.00000" xyz="-0.00134 -0.00095 0.04905"/>
			<mass value="0.39042"/>
			<inertia ixx="472.28631" ixy="0" ixz="0" iyy="324.96502" iyz="0" izz="254.48386"/>
		</inertial>
		<collision>
			<origin rpy="0.00000 -0.00000 0.00000" xyz="0.00000 0.00000 0.00000"/>
			<geometry>
				<mesh filename="unknown_file" scale="1.00000 1.00000 1.00000"/>
			</geometry>
		</collision>
	</link>
	<link name="link0_5">
		<inertial>
			<origin rpy="0.00000 -0.00000 0.00000" xyz="0.00000 0.00000 0.00000"/>
			<mass value="0.00000"/>
			<inertia ixx="0.00000" ixy="0" ixz="0" iyy="0.00000" iyz="0" izz="0.00000"/>
		</inertial>
	</link>
	<link name="head_link">
		<inertial>
			<origin rpy="0.00000 -0.00000 0.00000" xyz="0.00462 0.08027 -0.01673"/>
			<mass value="1.02997"/>
			<inertia ixx="11756.43699" ixy="0" ixz="0" iyy="10331.75798" iyz="0" izz="5447.40997"/>
		</inertial>
		<collision>
			<origin rpy="0.00000 -0.00000 0.00000" xyz="0.00000 0.00000 0.00000"/>
			<geometry>
				<mesh filename="unknown_file" scale="1.00000 1.00000 1.00000"/>
			</geometry>
		</collision>
	</link>
	<link name="link0_7">
		<inertial>
			<origin rpy="0.00000 -0.00000 0.00000" xyz="0.00000 0.00000 0.00000"/>
			<mass value="0.00000"/>
			<inertia ixx="0.00000" ixy="0" ixz="0" iyy="0.00000" iyz="0" izz="0.00000"/>
		</inertial>
	</link>
	<link name="right_shoulder_pitch_link">
		<inertial>
			<origin rpy="0.00000 -0.00000 0.00000" xyz="0.00351 -0.00096 0.04974"/>
			<mass value="0.42860"/>
			<inertia ixx="593.36520" ixy="0" ixz="0" iyy="403.47472" iyz="0" izz="391.16710"/>
		</inertial>
		<collision>
			<origin rpy="0.00000 -0.00000 0.00000" xyz="0.00000 0.00000 0.00000"/>
			<geometry>
				<mesh filename="unknown_file" scale="1.00000 1.00000 1.00000"/>
			</geometry>
		</collision>
	</link>
	<link name="link0_9">
		<inertial>
			<origin rpy="0.00000 -0.00000 0.00000" xyz="0.00000 0.00000 0.00000"/>
			<mass value="0.00000"/>
			<inertia ixx="0.00000" ixy="0" ixz="0" iyy="0.00000" iyz="0" izz="0.00000"/>
		</inertial>
	</link>
	<link name="right_shoulder_roll_link">
		<inertial>
			<origin rpy="0.00000 -0.00000 0.00000" xyz="0.00001 -0.10267 -0.01893"/>
			<mass value="0.45915"/>
			<inertia ixx="1213.40150" ixy="0" ixz="0" iyy="490.61625" iyz="0" izz="1213.55232"/>
		</inertial>
		<collision>
			<origin rpy="0.00000 -0.00000 0.00000" xyz="0.00000 0.00000 0.00000"/>
			<geometry>
				<mesh filename="unknown_file" scale="1.00000 1.00000 1.00000"/>
			</geometry>
		</collision>
	</link>
	<link name="link0_11">
		<inertial>
			<origin rpy="0.00000 -0.00000 0.00000" xyz="0.00000 0.00000 0.00000"/>
			<mass value="0.00000"/>
			<inertia ixx="0.00000" ixy="0" ixz="0" iyy="0.00000" iyz="0" izz="0.00000"/>
		</inertial>
	</link>
	<link name="right_shoulder_yaw_link">
		<inertial>
			<origin rpy="0.00000 -0.00000 0.00000" xyz="-0.00323 0.00090 -0.11620"/>
			<mass value="0.46273"/>
			<inertia ixx="1364.52054" ixy="0" ixz="0" iyy="1159.50683" iyz="0" izz="422.32034"/>
		</inertial>
		<collision>
			<origin rpy="0.00000 -0.00000 0.00000" xyz="0.00000 0.00000 0.00000"/>
			<geometry>
				<mesh filename="unknown_file" scale="1.00000 1.00000 1.00000"/>
			</geometry>
		</collision>
	</link>
	<link name="link0_13">
		<inertial>
			<origin rpy="0.00000 -0.00000 0.00000" xyz="0.00000 0.00000 0.00000"/>
			<mass value="0.00000"/>
			<inertia ixx="0.00000" ixy="0" ixz="0" iyy="0.00000" iyz="0" izz="0.00000"/>
		</inertial>
	</link>
	<link name="right_elbow_link">
		<inertial>
			<origin rpy="0.00000 -0.00000 0.00000" xyz="0.00007 -0.08173 -0.02591"/>
			<mass value="0.08453"/>
			<inertia ixx="508.50865" ixy="0" ixz="0" iyy="38.65271" iyz="0" izz="505.19105"/>
		</inertial>
		<collision>
			<origin rpy="0.00000 -0.00000 0.00000" xyz="0.00000 0.00000 0.00000"/>
			<geometry>
				<mesh filename="unknown_file" scale="1.00000 1.00000 1.00000"/>
			</geometry>
		</collision>
	</link>
	<link name="right_hand_link">
		<inertial>
			<origin rpy="0.00000 -0.00000 0.00000" xyz="-0.00013 0.03167 -0.00001"/>
			<mass value="0.32307"/>
			<inertia ixx="414.87501" ixy="0" ixz="0" iyy="212.65401" iyz="0" izz="414.87501"/>
		</inertial>
		<collision>
			<origin rpy="0.00000 -0.00000 0.00000" xyz="0.00000 0.00000 0.00000"/>
			<geometry>
				<mesh filename="unknown_file" scale="1.00000 1.00000 1.00000"/>
			</geometry>
		</collision>
	</link>
	<link name="link0_16">
		<inertial>
			<origin rpy="0.00000 -0.00000 0.00000" xyz="0.00000 0.00000 0.00000"/>
			<mass value="0.00000"/>
			<inertia ixx="0.00000" ixy="0" ixz="0" iyy="0.00000" iyz="0" izz="0.00000"/>
		</inertial>
	</link>
	<link name="left_shoulder_pitch_link">
		<inertial>
			<origin rpy="0.00000 -0.00000 0.00000" xyz="0.00354 -0.00097 -0.04969"/>
			<mass value="0.41980"/>
			<inertia ixx="581.17959" ixy="0" ixz="0" iyy="395.18878" iyz="0" izz="383.13391"/>
		</inertial>
		<collision>
			<origin rpy="0.00000 -0.00000 0.00000" xyz="0.00000 0.00000 0.00000"/>
			<geometry>
				<mesh filename="unknown_file" scale="1.00000 1.00000 1.00000"/>
			</geometry>
		</collision>
	</link>
	<link name="link0_18">
		<inertial>
			<origin rpy="0.00000 -0.00000 0.00000" xyz="0.00000 0.00000 0.00000"/>
			<mass value="0.00000"/>
			<inertia ixx="0.00000" ixy="0" ixz="0" iyy="0.00000" iyz="0" izz="0.00000"/>
		</inertial>
	</link>
	<link name="left_shoulder_roll_link">
		<inertial>
			<origin rpy="0.00000 -0.00000 0.00000" xyz="0.00001 -0.10267 0.01893"/>
			<mass value="0.45916"/>
			<inertia ixx="1213.41202" ixy="0" ixz="0" iyy="490.62050" iyz="0" izz="1213.56284"/>
		</inertial>
		<collision>
			<origin rpy="0.00000 -0.00000 0.00000" xyz="0.00000 0.00000 0.00000"/>
			<geometry>
				<mesh filename="unknown_file" scale="1.00000 1.00000 1.00000"/>
			</geometry>
		</collision>
	</link>
	<link name="link0_20">
		<inertial>
			<origin rpy="0.00000 -0.00000 0.00000" xyz="0.00000 0.00000 0.00000"/>
			<mass value="0.00000"/>
			<inertia ixx="0.00000" ixy="0" ixz="0" iyy="0.00000" iyz="0" izz="0.00000"/>
		</inertial>
	</link>
	<link name="left_shoulder_yaw_link">
		<inertial>
			<origin rpy="0.00000 -0.00000 0.00000" xyz="-0.00323 0.00090 0.11620"/>
			<mass value="0.46273"/>
			<inertia ixx="1364.52054" ixy="0" ixz="0" iyy="1159.50683" iyz="0" izz="422.32034"/>
		</inertial>
		<collision>
			<origin rpy="0.00000 -0.00000 0.00000" xyz="0.00000 0.00000 0.00000"/>
			<geometry>
				<mesh filename="unknown_file" scale="1.00000 1.00000 1.00000"/>
			</geometry>
		</collision>
	</link>
	<link name="link0_22">
		<inertial>
			<origin rpy="0.00000 -0.00000 0.00000" xyz="0.00000 0.00000 0.00000"/>
			<mass value="0.00000"/>
			<inertia ixx="0.00000" ixy="0" ixz="0" iyy="0.00000" iyz="0" izz="0.00000"/>
		</inertial>
	</link>
	<link name="left_elbow_link">
		<inertial>
			<origin rpy="0.00000 -0.00000 0.00000" xyz="0.00007 -0.08173 0.02592"/>
			<mass value="0.08453"/>
			<inertia ixx="508.53030" ixy="0" ixz="0" iyy="38.65435" iyz="0" izz="505.21256"/>
		</inertial>
		<collision>
			<origin rpy="0.00000 -0.00000 0.00000" xyz="0.00000 0.00000 0.00000"/>
			<geometry>
				<mesh filename="unknown_file" scale="1.00000 1.00000 1.00000"/>
			</geometry>
		</collision>
	</link>
	<link name="left_hand_link">
		<inertial>
			<origin rpy="0.00000 -0.00000 0.00000" xyz="-0.00013 0.03167 -0.00001"/>
			<mass value="0.32307"/>
			<inertia ixx="414.87501" ixy="0" ixz="0" iyy="212.65401" iyz="0" izz="414.87501"/>
		</inertial>
		<collision>
			<origin rpy="0.00000 -0.00000 0.00000" xyz="0.00000 0.00000 0.00000"/>
			<geometry>
				<mesh filename="unknown_file" scale="1.00000 1.00000 1.00000"/>
			</geometry>
		</collision>
	</link>
	<link name="link0_25">
		<inertial>
			<origin rpy="0.00000 -0.00000 0.00000" xyz="0.00000 0.00000 0.00000"/>
			<mass value="0.00000"/>
			<inertia ixx="0.00000" ixy="0" ixz="0" iyy="0.00000" iyz="0" izz="0.00000"/>
		</inertial>
	</link>
	<link name="axle_1_link">
		<inertial>
			<origin rpy="0.00000 -0.00000 0.00000" xyz="-0.00002 0.00000 0.00309"/>
			<mass value="0.10507"/>
			<inertia ixx="87.15543" ixy="0" ixz="0" iyy="87.15543" iyz="0" izz="158.77858"/>
		</inertial>
		<collision>
			<origin rpy="0.00000 -0.00000 0.00000" xyz="0.00000 0.00000 0.00000"/>
			<geometry>
				<mesh filename="unknown_file" scale="1.00000 1.00000 1.00000"/>
			</geometry>
		</collision>
	</link>
	<link name="link0_27">
		<inertial>
			<origin rpy="0.00000 -0.00000 0.00000" xyz="0.00000 0.00000 0.00000"/>
			<mass value="0.00000"/>
			<inertia ixx="0.00000" ixy="0" ixz="0" iyy="0.00000" iyz="0" izz="0.00000"/>
		</inertial>
	</link>
	<link name="fat_roller_1_1_link">
		<inertial>
			<origin rpy="0.00000 -0.00000 0.00000" xyz="-0.00000 -0.00000 0.00000"/>
			<mass value="0.01600"/>
			<inertia ixx="1.42014" ixy="0" ixz="0" iyy="1.58255" iyz="0" izz="1.58275"/>
		</inertial>
		<collision>
			<origin rpy="0.00000 -0.00000 0.00000" xyz="0.00000 0.00000 0.00000"/>
			<geometry>
				<mesh filename="unknown_file" scale="1.00000 1.00000 1.00000"/>
			</geometry>
		</collision>
	</link>
	<link name="link0_29">
		<inertial>
			<origin rpy="0.00000 -0.00000 0.00000" xyz="0.00000 0.00000 0.00000"/>
			<mass value="0.00000"/>
			<inertia ixx="0.00000" ixy="0" ixz="0" iyy="0.00000" iyz="0" izz="0.00000"/>
		</inertial>
	</link>
	<link name="fat_roller_1_2_link">
		<inertial>
			<origin rpy="0.00000 -0.00000 0.00000" xyz="-0.00000 -0.00000 0.00000"/>
			<mass value="0.01600"/>
			<inertia ixx="1.42014" ixy="0" ixz="0" iyy="1.58255" iyz="0" izz="1.58275"/>
		</inertial>
		<collision>
			<origin rpy="0.00000 -0.00000 0.00000" xyz="0.00000 0.00000 0.00000"/>
			<geometry>
				<mesh filename="unknown_file" scale="1.00000 1.00000 1.00000"/>
			</geometry>
		</collision>
	</link>
	<link name="link0_31">
		<inertial>
			<origin rpy="0.00000 -0.00000 0.00000" xyz="0.00000 0.00000 0.00000"/>
			<mass value="0.00000"/>
			<inertia ixx="0.00000" ixy="0" ixz="0" iyy="0.00000" iyz="0" izz="0.00000"/>
		</inertial>
	</link>
	<link name="fat_roller_1_3_link">
		<inertial>
			<origin rpy="0.00000 -0.00000 0.00000" xyz="-0.00000 -0.00000 0.00000"/>
			<mass value="0.01600"/>
			<inertia ixx="1.42014" ixy="0" ixz="0" iyy="1.58255" iyz="0" izz="1.58275"/>
		</inertial>
		<collision>
			<origin rpy="0.00000 -0.00000 0.00000" xyz="0.00000 0.00000 0.00000"/>
			<geometry>
				<mesh filename="unknown_file" scale="1.00000 1.00000 1.00000"/>
			</geometry>
		</collision>
	</link>
	<link name="link0_33">
		<inertial>
			<origin rpy="0.00000 -0.00000 0.00000" xyz="0.00000 0.00000 0.00000"/>
			<mass value="0.00000"/>
			<inertia ixx="0.00000" ixy="0" ixz="0" iyy="0.00000" iyz="0" izz="0.00000"/>
		</inertial>
	</link>
	<link name="fat_roller_1_4_link">
		<inertial>
			<origin rpy="0.00000 -0.00000 0.00000" xyz="-0.00000 -0.00000 0.00000"/>
			<mass value="0.01600"/>
			<inertia ixx="1.42014" ixy="0" ixz="0" iyy="1.58255" iyz="0" izz="1.58275"/>
		</inertial>
		<collision>
			<origin rpy="0.00000 -0.00000 0.00000" xyz="0.00000 0.00000 0.00000"/>
			<geometry>
				<mesh filename="unknown_file" scale="1.00000 1.00000 1.00000"/>
			</geometry>
		</collision>
	</link>
	<link name="link0_35">
		<inertial>
			<origin rpy="0.00000 -0.00000 0.00000" xyz="0.00000 0.00000 0.00000"/>
			<mass value="0.00000"/>
			<inertia ixx="0.00000" ixy="0" ixz="0" iyy="0.00000" iyz="0" izz="0.00000"/>
		</inertial>
	</link>
	<link name="fat_roller_1_5_link">
		<inertial>
			<origin rpy="0.00000 -0.00000 0.00000" xyz="-0.00000 -0.00000 0.00000"/>
			<mass value="0.01600"/>
			<inertia ixx="1.42014" ixy="0" ixz="0" iyy="1.58255" iyz="0" izz="1.58275"/>
		</inertial>
		<collision>
			<origin rpy="0.00000 -0.00000 0.00000" xyz="0.00000 0.00000 0.00000"/>
			<geometry>
				<mesh filename="unknown_file" scale="1.00000 1.00000 1.00000"/>
			</geometry>
		</collision>
	</link>
	<link name="link0_37">
		<inertial>
			<origin rpy="0.00000 -0.00000 0.00000" xyz="0.00000 0.00000 0.00000"/>
			<mass value="0.00000"/>
			<inertia ixx="0.00000" ixy="0" ixz="0" iyy="0.00000" iyz="0" izz="0.00000"/>
		</inertial>
	</link>
	<link name="fat_roller_1_6_link">
		<inertial>
			<origin rpy="0.00000 -0.00000 0.00000" xyz="-0.00000 -0.00000 0.00000"/>
			<mass value="0.01600"/>
			<inertia ixx="1.42014" ixy="0" ixz="0" iyy="1.58255" iyz="0" izz="1.58275"/>
		</inertial>
		<collision>
			<origin rpy="0.00000 -0.00000 0.00000" xyz="0.00000 0.00000 0.00000"/>
			<geometry>
				<mesh filename="unknown_file" scale="1.00000 1.00000 1.00000"/>
			</geometry>
		</collision>
	</link>
	<link name="link0_39">
		<inertial>
			<origin rpy="0.00000 -0.00000 0.00000" xyz="0.00000 0.00000 0.00000"/>
			<mass value="0.00000"/>
			<inertia ixx="0.00000" ixy="0" ixz="0" iyy="0.00000" iyz="0" izz="0.00000"/>
		</inertial>
	</link>
	<link name="thin_roller_1_1_link">
		<inertial>
			<origin rpy="0.00000 -0.00000 0.00000" xyz="0.00000 -0.00000 0.00000"/>
			<mass value="0.00864"/>
			<inertia ixx="0.28519" ixy="0" ixz="0" iyy="0.57772" iyz="0" izz="0.57772"/>
		</inertial>
		<collision>
			<origin rpy="0.00000 -0.00000 0.00000" xyz="0.00000 0.00000 0.00000"/>
			<geometry>
				<mesh filename="unknown_file" scale="1.00000 1.00000 1.00000"/>
			</geometry>
		</collision>
	</link>
	<link name="link0_41">
		<inertial>
			<origin rpy="0.00000 -0.00000 0.00000" xyz="0.00000 0.00000 0.00000"/>
			<mass value="0.00000"/>
			<inertia ixx="0.00000" ixy="0" ixz="0" iyy="0.00000" iyz="0" izz="0.00000"/>
		</inertial>
	</link>
	<link name="thin_roller_1_2_link">
		<inertial>
			<origin rpy="0.00000 -0.00000 0.00000" xyz="0.00000 -0.00000 0.00000"/>
			<mass value="0.00864"/>
			<inertia ixx="0.28519" ixy="0" ixz="0" iyy="0.57772" iyz="0" izz="0.57772"/>
		</inertial>
		<collision>
			<origin rpy="0.00000 -0.00000 0.00000" xyz="0.00000 0.00000 0.00000"/>
			<geometry>
				<mesh filename="unknown_file" scale="1.00000 1.00000 1.00000"/>
			</geometry>
		</collision>
	</link>
	<link name="link0_43">
		<inertial>
			<origin rpy="0.00000 -0.00000 0.00000" xyz="0.00000 0.00000 0.00000"/>
			<mass value="0.00000"/>
			<inertia ixx="0.00000" ixy="0" ixz="0" iyy="0.00000" iyz="0" izz="0.00000"/>
		</inertial>
	</link>
	<link name="thin_roller_1_3_link">
		<inertial>
			<origin rpy="0.00000 -0.00000 0.00000" xyz="0.00000 -0.00000 0.00000"/>
			<mass value="0.00864"/>
			<inertia ixx="0.28519" ixy="0" ixz="0" iyy="0.57772" iyz="0" izz="0.57772"/>
		</inertial>
		<collision>
			<origin rpy="0.00000 -0.00000 0.00000" xyz="0.00000 0.00000 0.00000"/>
			<geometry>
				<mesh filename="unknown_file" scale="1.00000 1.00000 1.00000"/>
			</geometry>
		</collision>
	</link>
	<link name="link0_45">
		<inertial>
			<origin rpy="0.00000 -0.00000 0.00000" xyz="0.00000 0.00000 0.00000"/>
			<mass value="0.00000"/>
			<inertia ixx="0.00000" ixy="0" ixz="0" iyy="0.00000" iyz="0" izz="0.00000"/>
		</inertial>
	</link>
	<link name="thin_roller_1_4_link">
		<inertial>
			<origin rpy="0.00000 -0.00000 0.00000" xyz="0.00000 -0.00000 0.00000"/>
			<mass value="0.00864"/>
			<inertia ixx="0.28519" ixy="0" ixz="0" iyy="0.57772" iyz="0" izz="0.57772"/>
		</inertial>
		<collision>
			<origin rpy="0.00000 -0.00000 0.00000" xyz="0.00000 0.00000 0.00000"/>
			<geometry>
				<mesh filename="unknown_file" scale="1.00000 1.00000 1.00000"/>
			</geometry>
		</collision>
	</link>
	<link name="link0_47">
		<inertial>
			<origin rpy="0.00000 -0.00000 0.00000" xyz="0.00000 0.00000 0.00000"/>
			<mass value="0.00000"/>
			<inertia ixx="0.00000" ixy="0" ixz="0" iyy="0.00000" iyz="0" izz="0.00000"/>
		</inertial>
	</link>
	<link name="thin_roller_1_5_link">
		<inertial>
			<origin rpy="0.00000 -0.00000 0.00000" xyz="0.00000 -0.00000 0.00000"/>
			<mass value="0.00864"/>
			<inertia ixx="0.28519" ixy="0" ixz="0" iyy="0.57772" iyz="0" izz="0.57772"/>
		</inertial>
		<collision>
			<origin rpy="0.00000 -0.00000 0.00000" xyz="0.00000 0.00000 0.00000"/>
			<geometry>
				<mesh filename="unknown_file" scale="1.00000 1.00000 1.00000"/>
			</geometry>
		</collision>
	</link>
	<link name="link0_49">
		<inertial>
			<origin rpy="0.00000 -0.00000 0.00000" xyz="0.00000 0.00000 0.00000"/>
			<mass value="0.00000"/>
			<inertia ixx="0.00000" ixy="0" ixz="0" iyy="0.00000" iyz="0" izz="0.00000"/>
		</inertial>
	</link>
	<link name="thin_roller_1_6_link">
		<inertial>
			<origin rpy="0.00000 -0.00000 0.00000" xyz="0.00000 -0.00000 0.00000"/>
			<mass value="0.00864"/>
			<inertia ixx="0.28519" ixy="0" ixz="0" iyy="0.57772" iyz="0" izz="0.57772"/>
		</inertial>
		<collision>
			<origin rpy="0.00000 -0.00000 0.00000" xyz="0.00000 0.00000 0.00000"/>
			<geometry>
				<mesh filename="unknown_file" scale="1.00000 1.00000 1.00000"/>
			</geometry>
		</collision>
	</link>
	<link name="link0_51">
		<inertial>
			<origin rpy="0.00000 -0.00000 0.00000" xyz="0.00000 0.00000 0.00000"/>
			<mass value="0.00000"/>
			<inertia ixx="0.00000" ixy="0" ixz="0" iyy="0.00000" iyz="0" izz="0.00000"/>
		</inertial>
	</link>
	<link name="axle_2_link">
		<inertial>
			<origin rpy="0.00000 -0.00000 0.00000" xyz="-0.00002 0.00000 0.00309"/>
			<mass value="0.10507"/>
			<inertia ixx="87.15543" ixy="0" ixz="0" iyy="87.15543" iyz="0" izz="158.77858"/>
		</inertial>
		<collision>
			<origin rpy="0.00000 -0.00000 0.00000" xyz="0.00000 0.00000 0.00000"/>
			<geometry>
				<mesh filename="unknown_file" scale="1.00000 1.00000 1.00000"/>
			</geometry>
		</collision>
	</link>
	<link name="link0_53">
		<inertial>
			<origin rpy="0.00000 -0.00000 0.00000" xyz="0.00000 0.00000 0.00000"/>
			<mass value="0.00000"/>
			<inertia ixx="0.00000" ixy="0" ixz="0" iyy="0.00000" iyz="0" izz="0.00000"/>
		</inertial>
	</link>
	<link name="fat_roller_2_1_link">
		<inertial>
			<origin rpy="0.00000 -0.00000 0.00000" xyz="-0.00000 -0.00000 0.00000"/>
			<mass value="0.01600"/>
			<inertia ixx="1.42014" ixy="0" ixz="0" iyy="1.58255" iyz="0" izz="1.58275"/>
		</inertial>
		<collision>
			<origin rpy="0.00000 -0.00000 0.00000" xyz="0.00000 0.00000 0.00000"/>
			<geometry>
				<mesh filename="unknown_file" scale="1.00000 1.00000 1.00000"/>
			</geometry>
		</collision>
	</link>
	<link name="link0_55">
		<inertial>
			<origin rpy="0.00000 -0.00000 0.00000" xyz="0.00000 0.00000 0.00000"/>
			<mass value="0.00000"/>
			<inertia ixx="0.00000" ixy="0" ixz="0" iyy="0.00000" iyz="0" izz="0.00000"/>
		</inertial>
	</link>
	<link name="fat_roller_2_2_link">
		<inertial>
			<origin rpy="0.00000 -0.00000 0.00000" xyz="-0.00000 -0.00000 0.00000"/>
			<mass value="0.01600"/>
			<inertia ixx="1.42014" ixy="0" ixz="0" iyy="1.58255" iyz="0" izz="1.58275"/>
		</inertial>
		<collision>
			<origin rpy="0.00000 -0.00000 0.00000" xyz="0.00000 0.00000 0.00000"/>
			<geometry>
				<mesh filename="unknown_file" scale="1.00000 1.00000 1.00000"/>
			</geometry>
		</collision>
	</link>
	<link name="link0_57">
		<inertial>
			<origin rpy="0.00000 -0.00000 0.00000" xyz="0.00000 0.00000 0.00000"/>
			<mass value="0.00000"/>
			<inertia ixx="0.00000" ixy="0" ixz="0" iyy="0.00000" iyz="0" izz="0.00000"/>
		</inertial>
	</link>
	<link name="fat_roller_2_3_link">
		<inertial>
			<origin rpy="0.00000 -0.00000 0.00000" xyz="-0.00000 -0.00000 0.00000"/>
			<mass value="0.01600"/>
			<inertia ixx="1.42014" ixy="0" ixz="0" iyy="1.58255" iyz="0" izz="1.58275"/>
		</inertial>
		<collision>
			<origin rpy="0.00000 -0.00000 0.00000" xyz="0.00000 0.00000 0.00000"/>
			<geometry>
				<mesh filename="unknown_file" scale="1.00000 1.00000 1.00000"/>
			</geometry>
		</collision>
	</link>
	<link name="link0_59">
		<inertial>
			<origin rpy="0.00000 -0.00000 0.00000" xyz="0.00000 0.00000 0.00000"/>
			<mass value="0.00000"/>
			<inertia ixx="0.00000" ixy="0" ixz="0" iyy="0.00000" iyz="0" izz="0.00000"/>
		</inertial>
	</link>
	<link name="fat_roller_2_4_link">
		<inertial>
			<origin rpy="0.00000 -0.00000 0.00000" xyz="-0.00000 -0.00000 0.00000"/>
			<mass value="0.01600"/>
			<inertia ixx="1.42014" ixy="0" ixz="0" iyy="1.58255" iyz="0" izz="1.58275"/>
		</inertial>
		<collision>
			<origin rpy="0.00000 -0.00000 0.00000" xyz="0.00000 0.00000 0.00000"/>
			<geometry>
				<mesh filename="unknown_file" scale="1.00000 1.00000 1.00000"/>
			</geometry>
		</collision>
	</link>
	<link name="link0_61">
		<inertial>
			<origin rpy="0.00000 -0.00000 0.00000" xyz="0.00000 0.00000 0.00000"/>
			<mass value="0.00000"/>
			<inertia ixx="0.00000" ixy="0" ixz="0" iyy="0.00000" iyz="0" izz="0.00000"/>
		</inertial>
	</link>
	<link name="fat_roller_2_5_link">
		<inertial>
			<origin rpy="0.00000 -0.00000 0.00000" xyz="-0.00000 -0.00000 0.00000"/>
			<mass value="0.01600"/>
			<inertia ixx="1.42014" ixy="0" ixz="0" iyy="1.58255" iyz="0" izz="1.58275"/>
		</inertial>
		<collision>
			<origin rpy="0.00000 -0.00000 0.00000" xyz="0.00000 0.00000 0.00000"/>
			<geometry>
				<mesh filename="unknown_file" scale="1.00000 1.00000 1.00000"/>
			</geometry>
		</collision>
	</link>
	<link name="link0_63">
		<inertial>
			<origin rpy="0.00000 -0.00000 0.00000" xyz="0.00000 0.00000 0.00000"/>
			<mass value="0.00000"/>
			<inertia ixx="0.00000" ixy="0" ixz="0" iyy="0.00000" iyz="0" izz="0.00000"/>
		</inertial>
	</link>
	<link name="fat_roller_2_6_link">
		<inertial>
			<origin rpy="0.00000 -0.00000 0.00000" xyz="-0.00000 -0.00000 0.00000"/>
			<mass value="0.01600"/>
			<inertia ixx="1.42014" ixy="0" ixz="0" iyy="1.58255" iyz="0" izz="1.58275"/>
		</inertial>
		<collision>
			<origin rpy="0.00000 -0.00000 0.00000" xyz="0.00000 0.00000 0.00000"/>
			<geometry>
				<mesh filename="unknown_file" scale="1.00000 1.00000 1.00000"/>
			</geometry>
		</collision>
	</link>
	<link name="link0_65">
		<inertial>
			<origin rpy="0.00000 -0.00000 0.00000" xyz="0.00000 0.00000 0.00000"/>
			<mass value="0.00000"/>
			<inertia ixx="0.00000" ixy="0" ixz="0" iyy="0.00000" iyz="0" izz="0.00000"/>
		</inertial>
	</link>
	<link name="thin_roller_2_1_link">
		<inertial>
			<origin rpy="0.00000 -0.00000 0.00000" xyz="0.00000 -0.00000 0.00000"/>
			<mass value="0.00864"/>
			<inertia ixx="0.28519" ixy="0" ixz="0" iyy="0.57772" iyz="0" izz="0.57772"/>
		</inertial>
		<collision>
			<origin rpy="0.00000 -0.00000 0.00000" xyz="0.00000 0.00000 0.00000"/>
			<geometry>
				<mesh filename="unknown_file" scale="1.00000 1.00000 1.00000"/>
			</geometry>
		</collision>
	</link>
	<link name="link0_67">
		<inertial>
			<origin rpy="0.00000 -0.00000 0.00000" xyz="0.00000 0.00000 0.00000"/>
			<mass value="0.00000"/>
			<inertia ixx="0.00000" ixy="0" ixz="0" iyy="0.00000" iyz="0" izz="0.00000"/>
		</inertial>
	</link>
	<link name="thin_roller_2_2_link">
		<inertial>
			<origin rpy="0.00000 -0.00000 0.00000" xyz="0.00000 -0.00000 0.00000"/>
			<mass value="0.00864"/>
			<inertia ixx="0.28519" ixy="0" ixz="0" iyy="0.57772" iyz="0" izz="0.57772"/>
		</inertial>
		<collision>
			<origin rpy="0.00000 -0.00000 0.00000" xyz="0.00000 0.00000 0.00000"/>
			<geometry>
				<mesh filename="unknown_file" scale="1.00000 1.00000 1.00000"/>
			</geometry>
		</collision>
	</link>
	<link name="link0_69">
		<inertial>
			<origin rpy="0.00000 -0.00000 0.00000" xyz="0.00000 0.00000 0.00000"/>
			<mass value="0.00000"/>
			<inertia ixx="0.00000" ixy="0" ixz="0" iyy="0.00000" iyz="0" izz="0.00000"/>
		</inertial>
	</link>
	<link name="thin_roller_2_3_link">
		<inertial>
			<origin rpy="0.00000 -0.00000 0.00000" xyz="0.00000 -0.00000 0.00000"/>
			<mass value="0.00864"/>
			<inertia ixx="0.28519" ixy="0" ixz="0" iyy="0.57772" iyz="0" izz="0.57772"/>
		</inertial>
		<collision>
			<origin rpy="0.00000 -0.00000 0.00000" xyz="0.00000 0.00000 0.00000"/>
			<geometry>
				<mesh filename="unknown_file" scale="1.00000 1.00000 1.00000"/>
			</geometry>
		</collision>
	</link>
	<link name="link0_71">
		<inertial>
			<origin rpy="0.00000 -0.00000 0.00000" xyz="0.00000 0.00000 0.00000"/>
			<mass value="0.00000"/>
			<inertia ixx="0.00000" ixy="0" ixz="0" iyy="0.00000" iyz="0" izz="0.00000"/>
		</inertial>
	</link>
	<link name="thin_roller_2_4_link">
		<inertial>
			<origin rpy="0.00000 -0.00000 0.00000" xyz="0.00000 -0.00000 0.00000"/>
			<mass value="0.00864"/>
			<inertia ixx="0.28519" ixy="0" ixz="0" iyy="0.57772" iyz="0" izz="0.57772"/>
		</inertial>
		<collision>
			<origin rpy="0.00000 -0.00000 0.00000" xyz="0.00000 0.00000 0.00000"/>
			<geometry>
				<mesh filename="unknown_file" scale="1.00000 1.00000 1.00000"/>
			</geometry>
		</collision>
	</link>
	<link name="link0_73">
		<inertial>
			<origin rpy="0.00000 -0.00000 0.00000" xyz="0.00000 0.00000 0.00000"/>
			<mass value="0.00000"/>
			<inertia ixx="0.00000" ixy="0" ixz="0" iyy="0.00000" iyz="0" izz="0.00000"/>
		</inertial>
	</link>
	<link name="thin_roller_2_5_link">
		<inertial>
			<origin rpy="0.00000 -0.00000 0.00000" xyz="0.00000 -0.00000 0.00000"/>
			<mass value="0.00864"/>
			<inertia ixx="0.28519" ixy="0" ixz="0" iyy="0.57772" iyz="0" izz="0.57772"/>
		</inertial>
		<collision>
			<origin rpy="0.00000 -0.00000 0.00000" xyz="0.00000 0.00000 0.00000"/>
			<geometry>
				<mesh filename="unknown_file" scale="1.00000 1.00000 1.00000"/>
			</geometry>
		</collision>
	</link>
	<link name="link0_75">
		<inertial>
			<origin rpy="0.00000 -0.00000 0.00000" xyz="0.00000 0.00000 0.00000"/>
			<mass value="0.00000"/>
			<inertia ixx="0.00000" ixy="0" ixz="0" iyy="0.00000" iyz="0" izz="0.00000"/>
		</inertial>
	</link>
	<link name="thin_roller_2_6_link">
		<inertial>
			<origin rpy="0.00000 -0.00000 0.00000" xyz="0.00000 -0.00000 0.00000"/>
			<mass value="0.00864"/>
			<inertia ixx="0.28519" ixy="0" ixz="0" iyy="0.57772" iyz="0" izz="0.57772"/>
		</inertial>
		<collision>
			<origin rpy="0.00000 -0.00000 0.00000" xyz="0.00000 0.00000 0.00000"/>
			<geometry>
				<mesh filename="unknown_file" scale="1.00000 1.00000 1.00000"/>
			</geometry>
		</collision>
	</link>
	<link name="link0_77">
		<inertial>
			<origin rpy="0.00000 -0.00000 0.00000" xyz="0.00000 0.00000 0.00000"/>
			<mass value="0.00000"/>
			<inertia ixx="0.00000" ixy="0" ixz="0" iyy="0.00000" iyz="0" izz="0.00000"/>
		</inertial>
	</link>
	<link name="axle_3_link">
		<inertial>
			<origin rpy="0.00000 -0.00000 0.00000" xyz="-0.00002 0.00000 0.00309"/>
			<mass value="0.10507"/>
			<inertia ixx="87.15543" ixy="0" ixz="0" iyy="87.15543" iyz="0" izz="158.77858"/>
		</inertial>
		<collision>
			<origin rpy="0.00000 -0.00000 0.00000" xyz="0.00000 0.00000 0.00000"/>
			<geometry>
				<mesh filename="unknown_file" scale="1.00000 1.00000 1.00000"/>
			</geometry>
		</collision>
	</link>
	<link name="link0_79">
		<inertial>
			<origin rpy="0.00000 -0.00000 0.00000" xyz="0.00000 0.00000 0.00000"/>
			<mass value="0.00000"/>
			<inertia ixx="0.00000" ixy="0" ixz="0" iyy="0.00000" iyz="0" izz="0.00000"/>
		</inertial>
	</link>
	<link name="fat_roller_3_1_link">
		<inertial>
			<origin rpy="0.00000 -0.00000 0.00000" xyz="-0.00000 -0.00000 0.00000"/>
			<mass value="0.01600"/>
			<inertia ixx="1.42014" ixy="0" ixz="0" iyy="1.58255" iyz="0" izz="1.58275"/>
		</inertial>
		<collision>
			<origin rpy="0.00000 -0.00000 0.00000" xyz="0.00000 0.00000 0.00000"/>
			<geometry>
				<mesh filename="unknown_file" scale="1.00000 1.00000 1.00000"/>
			</geometry>
		</collision>
	</link>
	<link name="link0_81">
		<inertial>
			<origin rpy="0.00000 -0.00000 0.00000" xyz="0.00000 0.00000 0.00000"/>
			<mass value="0.00000"/>
			<inertia ixx="0.00000" ixy="0" ixz="0" iyy="0.00000" iyz="0" izz="0.00000"/>
		</inertial>
	</link>
	<link name="fat_roller_3_2_link">
		<inertial>
			<origin rpy="0.00000 -0.00000 0.00000" xyz="-0.00000 -0.00000 0.00000"/>
			<mass value="0.01600"/>
			<inertia ixx="1.42014" ixy="0" ixz="0" iyy="1.58255" iyz="0" izz="1.58275"/>
		</inertial>
		<collision>
			<origin rpy="0.00000 -0.00000 0.00000" xyz="0.00000 0.00000 0.00000"/>
			<geometry>
				<mesh filename="unknown_file" scale="1.00000 1.00000 1.00000"/>
			</geometry>
		</collision>
	</link>
	<link name="link0_83">
		<inertial>
			<origin rpy="0.00000 -0.00000 0.00000" xyz="0.00000 0.00000 0.00000"/>
			<mass value="0.00000"/>
			<inertia ixx="0.00000" ixy="0" ixz="0" iyy="0.00000" iyz="0" izz="0.00000"/>
		</inertial>
	</link>
	<link name="fat_roller_3_3_link">
		<inertial>
			<origin rpy="0.00000 -0.00000 0.00000" xyz="-0.00000 -0.00000 0.00000"/>
			<mass value="0.01600"/>
			<inertia ixx="1.42014" ixy="0" ixz="0" iyy="1.58255" iyz="0" izz="1.58275"/>
		</inertial>
		<collision>
			<origin rpy="0.00000 -0.00000 0.00000" xyz="0.00000 0.00000 0.00000"/>
			<geometry>
				<mesh filename="unknown_file" scale="1.00000 1.00000 1.00000"/>
			</geometry>
		</collision>
	</link>
	<link name="link0_85">
		<inertial>
			<origin rpy="0.00000 -0.00000 0.00000" xyz="0.00000 0.00000 0.00000"/>
			<mass value="0.00000"/>
			<inertia ixx="0.00000" ixy="0" ixz="0" iyy="0.00000" iyz="0" izz="0.00000"/>
		</inertial>
	</link>
	<link name="fat_roller_3_4_link">
		<inertial>
			<origin rpy="0.00000 -0.00000 0.00000" xyz="-0.00000 -0.00000 0.00000"/>
			<mass value="0.01600"/>
			<inertia ixx="1.42014" ixy="0" ixz="0" iyy="1.58255" iyz="0" izz="1.58275"/>
		</inertial>
		<collision>
			<origin rpy="0.00000 -0.00000 0.00000" xyz="0.00000 0.00000 0.00000"/>
			<geometry>
				<mesh filename="unknown_file" scale="1.00000 1.00000 1.00000"/>
			</geometry>
		</collision>
	</link>
	<link name="link0_87">
		<inertial>
			<origin rpy="0.00000 -0.00000 0.00000" xyz="0.00000 0.00000 0.00000"/>
			<mass value="0.00000"/>
			<inertia ixx="0.00000" ixy="0" ixz="0" iyy="0.00000" iyz="0" izz="0.00000"/>
		</inertial>
	</link>
	<link name="fat_roller_3_5_link">
		<inertial>
			<origin rpy="0.00000 -0.00000 0.00000" xyz="-0.00000 -0.00000 0.00000"/>
			<mass value="0.01600"/>
			<inertia ixx="1.42014" ixy="0" ixz="0" iyy="1.58255" iyz="0" izz="1.58275"/>
		</inertial>
		<collision>
			<origin rpy="0.00000 -0.00000 0.00000" xyz="0.00000 0.00000 0.00000"/>
			<geometry>
				<mesh filename="unknown_file" scale="1.00000 1.00000 1.00000"/>
			</geometry>
		</collision>
	</link>
	<link name="link0_89">
		<inertial>
			<origin rpy="0.00000 -0.00000 0.00000" xyz="0.00000 0.00000 0.00000"/>
			<mass value="0.00000"/>
			<inertia ixx="0.00000" ixy="0" ixz="0" iyy="0.00000" iyz="0" izz="0.00000"/>
		</inertial>
	</link>
	<link name="fat_roller_3_6_link">
		<inertial>
			<origin rpy="0.00000 -0.00000 0.00000" xyz="-0.00000 -0.00000 0.00000"/>
			<mass value="0.01600"/>
			<inertia ixx="1.42014" ixy="0" ixz="0" iyy="1.58255" iyz="0" izz="1.58275"/>
		</inertial>
		<collision>
			<origin rpy="0.00000 -0.00000 0.00000" xyz="0.00000 0.00000 0.00000"/>
			<geometry>
				<mesh filename="unknown_file" scale="1.00000 1.00000 1.00000"/>
			</geometry>
		</collision>
	</link>
	<link name="link0_91">
		<inertial>
			<origin rpy="0.00000 -0.00000 0.00000" xyz="0.00000 0.00000 0.00000"/>
			<mass value="0.00000"/>
			<inertia ixx="0.00000" ixy="0" ixz="0" iyy="0.00000" iyz="0" izz="0.00000"/>
		</inertial>
	</link>
	<link name="thin_roller_3_1_link">
		<inertial>
			<origin rpy="0.00000 -0.00000 0.00000" xyz="0.00000 -0.00000 0.00000"/>
			<mass value="0.00864"/>
			<inertia ixx="0.28519" ixy="0" ixz="0" iyy="0.57772" iyz="0" izz="0.57772"/>
		</inertial>
		<collision>
			<origin rpy="0.00000 -0.00000 0.00000" xyz="0.00000 0.00000 0.00000"/>
			<geometry>
				<mesh filename="unknown_file" scale="1.00000 1.00000 1.00000"/>
			</geometry>
		</collision>
	</link>
	<link name="link0_93">
		<inertial>
			<origin rpy="0.00000 -0.00000 0.00000" xyz="0.00000 0.00000 0.00000"/>
			<mass value="0.00000"/>
			<inertia ixx="0.00000" ixy="0" ixz="0" iyy="0.00000" iyz="0" izz="0.00000"/>
		</inertial>
	</link>
	<link name="thin_roller_3_2_link">
		<inertial>
			<origin rpy="0.00000 -0.00000 0.00000" xyz="0.00000 -0.00000 0.00000"/>
			<mass value="0.00864"/>
			<inertia ixx="0.28519" ixy="0" ixz="0" iyy="0.57772" iyz="0" izz="0.57772"/>
		</inertial>
		<collision>
			<origin rpy="0.00000 -0.00000 0.00000" xyz="0.00000 0.00000 0.00000"/>
			<geometry>
				<mesh filename="unknown_file" scale="1.00000 1.00000 1.00000"/>
			</geometry>
		</collision>
	</link>
	<link name="link0_95">
		<inertial>
			<origin rpy="0.00000 -0.00000 0.00000" xyz="0.00000 0.00000 0.00000"/>
			<mass value="0.00000"/>
			<inertia ixx="0.00000" ixy="0" ixz="0" iyy="0.00000" iyz="0" izz="0.00000"/>
		</inertial>
	</link>
	<link name="thin_roller_3_3_link">
		<inertial>
			<origin rpy="0.00000 -0.00000 0.00000" xyz="0.00000 -0.00000 0.00000"/>
			<mass value="0.00864"/>
			<inertia ixx="0.28519" ixy="0" ixz="0" iyy="0.57772" iyz="0" izz="0.57772"/>
		</inertial>
		<collision>
			<origin rpy="0.00000 -0.00000 0.00000" xyz="0.00000 0.00000 0.00000"/>
			<geometry>
				<mesh filename="unknown_file" scale="1.00000 1.00000 1.00000"/>
			</geometry>
		</collision>
	</link>
	<link name="link0_97">
		<inertial>
			<origin rpy="0.00000 -0.00000 0.00000" xyz="0.00000 0.00000 0.00000"/>
			<mass value="0.00000"/>
			<inertia ixx="0.00000" ixy="0" ixz="0" iyy="0.00000" iyz="0" izz="0.00000"/>
		</inertial>
	</link>
	<link name="thin_roller_3_4_link">
		<inertial>
			<origin rpy="0.00000 -0.00000 0.00000" xyz="0.00000 -0.00000 0.00000"/>
			<mass value="0.00864"/>
			<inertia ixx="0.28519" ixy="0" ixz="0" iyy="0.57772" iyz="0" izz="0.57772"/>
		</inertial>
		<collision>
			<origin rpy="0.00000 -0.00000 0.00000" xyz="0.00000 0.00000 0.00000"/>
			<geometry>
				<mesh filename="unknown_file" scale="1.00000 1.00000 1.00000"/>
			</geometry>
		</collision>
	</link>
	<link name="link0_99">
		<inertial>
			<origin rpy="0.00000 -0.00000 0.00000" xyz="0.00000 0.00000 0.00000"/>
			<mass value="0.00000"/>
			<inertia ixx="0.00000" ixy="0" ixz="0" iyy="0.00000" iyz="0" izz="0.00000"/>
		</inertial>
	</link>
	<link name="thin_roller_3_5_link">
		<inertial>
			<origin rpy="0.00000 -0.00000 0.00000" xyz="0.00000 -0.00000 0.00000"/>
			<mass value="0.00864"/>
			<inertia ixx="0.28519" ixy="0" ixz="0" iyy="0.57772" iyz="0" izz="0.57772"/>
		</inertial>
		<collision>
			<origin rpy="0.00000 -0.00000 0.00000" xyz="0.00000 0.00000 0.00000"/>
			<geometry>
				<mesh filename="unknown_file" scale="1.00000 1.00000 1.00000"/>
			</geometry>
		</collision>
	</link>
	<link name="link0_101">
		<inertial>
			<origin rpy="0.00000 -0.00000 0.00000" xyz="0.00000 0.00000 0.00000"/>
			<mass value="0.00000"/>
			<inertia ixx="0.00000" ixy="0" ixz="0" iyy="0.00000" iyz="0" izz="0.00000"/>
		</inertial>
	</link>
	<link name="thin_roller_3_6_link">
		<inertial>
			<origin rpy="0.00000 -0.00000 0.00000" xyz="0.00000 -0.00000 0.00000"/>
			<mass value="0.00864"/>
			<inertia ixx="0.28519" ixy="0" ixz="0" iyy="0.57772" iyz="0" izz="0.57772"/>
		</inertial>
		<collision>
			<origin rpy="0.00000 -0.00000 0.00000" xyz="0.00000 0.00000 0.00000"/>
			<geometry>
				<mesh filename="unknown_file" scale="1.00000 1.00000 1.00000"/>
			</geometry>
		</collision>
	</link>
	<joint name="jointfix_12_0" type="fixed">
		<parent link="base_link"/>
		<child link="torso_link"/>
		<dynamics damping="1.0" friction="0.0001"/>
		<origin rpy="0.00000 -0.00000 0.00000" xyz="-0.00000 -0.00000 0.44000"/>
		<axis xyz="0.00000 0.00000 0.00000"/>
	</joint>
	<joint name="neck_joint" type="continuous">
		<parent link="torso_link"/>
		<child link="link0_3"/>
		<dynamics damping="1.0" friction="0.0001"/>
		<origin rpy="0.00000 -0.00000 0.00000" xyz="-0.00000 0.00000 0.47400"/>
		<axis xyz="-0.00000 -0.00000 1.00000"/>
	</joint>
	<joint name="jointfix_1_3" type="fixed">
		<parent link="link0_3"/>
		<child link="neck_link"/>
		<dynamics damping="1.0" friction="0.0001"/>
		<origin rpy="0.00000 -0.00000 0.00000" xyz="0.00000 -0.00000 0.00000"/>
		<axis xyz="0.00000 0.00000 0.00000"/>
	</joint>
	<joint name="head_joint" type="continuous">
		<parent link="neck_link"/>
		<child link="link0_5"/>
		<dynamics damping="1.0" friction="0.0001"/>
		<origin rpy="0.00000 -0.00000 0.00000" xyz="0.01800 -0.00000 0.05200"/>
		<axis xyz="-0.00000 0.00000 1.00000"/>
	</joint>
	<joint name="jointfix_0_5" type="fixed">
		<parent link="link0_5"/>
		<child link="head_link"/>
		<dynamics damping="1.0" friction="0.0001"/>
		<origin rpy="0.00000 -0.00000 0.00000" xyz="-0.00000 0.00000 0.00000"/>
		<axis xyz="0.00000 0.00000 0.00000"/>
	</joint>
	<joint name="right_shoulder_pitch_joint" type="continuous">
		<parent link="torso_link"/>
		<child link="link0_7"/>
		<dynamics damping="1.0" friction="0.0001"/>
		<origin rpy="0.00000 -0.00000 0.00000" xyz="-0.00000 -0.15900 0.39000"/>
		<axis xyz="-0.00000 0.00000 1.00000"/>
	</joint>
	<joint name="jointfix_6_7" type="fixed">
		<parent link="link0_7"/>
		<child link="right_shoulder_pitch_link"/>
		<dynamics damping="1.0" friction="0.0001"/>
		<origin rpy="0.00000 -0.00000 0.00000" xyz="0.00000 -0.00000 0.00000"/>
		<axis xyz="0.00000 0.00000 0.00000"/>
	</joint>
	<joint name="right_shoulder_roll_joint" type="continuous">
		<parent link="right_shoulder_pitch_link"/>
		<child link="link0_9"/>
		<dynamics damping="1.0" friction="0.0001"/>
		<origin rpy="0.00000 -0.00000 0.00000" xyz="-0.01800 -0.00000 0.05200"/>
		<axis xyz="0.00000 0.00000 1.00000"/>
	</joint>
	<joint name="jointfix_5_9" type="fixed">
		<parent link="link0_9"/>
		<child link="right_shoulder_roll_link"/>
		<dynamics damping="1.0" friction="0.0001"/>
		<origin rpy="0.00000 -0.00000 0.00000" xyz="-0.00000 0.00000 -0.00000"/>
		<axis xyz="0.00000 0.00000 0.00000"/>
	</joint>
	<joint name="right_shoulder_yaw_joint" type="continuous">
		<parent link="right_shoulder_roll_link"/>
		<child link="link0_11"/>
		<dynamics damping="1.0" friction="0.0001"/>
		<origin rpy="0.00000 -0.00000 0.00000" xyz="-0.00000 -0.13400 -0.01800"/>
		<axis xyz="0.00000 0.00000 -1.00000"/>
	</joint>
	<joint name="jointfix_4_11" type="fixed">
		<parent link="link0_11"/>
		<child link="right_shoulder_yaw_link"/>
		<dynamics damping="1.0" friction="0.0001"/>
		<origin rpy="0.00000 -0.00000 0.00000" xyz="0.00000 0.00000 0.00000"/>
		<axis xyz="0.00000 0.00000 0.00000"/>
	</joint>
	<joint name="right_elbow_joint" type="continuous">
		<parent link="right_shoulder_yaw_link"/>
		<child link="link0_13"/>
		<dynamics damping="1.0" friction="0.0001"/>
		<origin rpy="0.00000 -0.00000 0.00000" xyz="-0.02650 0.00000 -0.16950"/>
		<axis xyz="-0.00000 0.00000 -1.00000"/>
	</joint>
	<joint name="jointfix_3_13" type="fixed">
		<parent link="link0_13"/>
		<child link="right_elbow_link"/>
		<dynamics damping="1.0" friction="0.0001"/>
		<origin rpy="0.00000 -0.00000 0.00000" xyz="-0.00000 -0.00000 0.04450"/>
		<axis xyz="0.00000 0.00000 0.00000"/>
	</joint>
	<joint name="jointfix_2_12" type="fixed">
		<parent link="right_elbow_link"/>
		<child link="right_hand_link"/>
		<dynamics damping="1.0" friction="0.0001"/>
		<origin rpy="0.00000 -0.00000 0.00000" xyz="0.00000 -0.23800 -0.02650"/>
		<axis xyz="0.00000 0.00000 0.00000"/>
	</joint>
	<joint name="left_shoulder_pitch_joint" type="continuous">
		<parent link="torso_link"/>
		<child link="link0_16"/>
		<dynamics damping="1.0" friction="0.0001"/>
		<origin rpy="0.00000 -0.00000 0.00000" xyz="-0.00000 0.15900 0.39000"/>
		<axis xyz="0.00000 -0.00000 -1.00000"/>
	</joint>
	<joint name="jointfix_11_16" type="fixed">
		<parent link="link0_16"/>
		<child link="left_shoulder_pitch_link"/>
		<dynamics damping="1.0" friction="0.0001"/>
		<origin rpy="0.00000 -0.00000 0.00000" xyz="0.00000 -0.00000 0.00000"/>
		<axis xyz="0.00000 0.00000 0.00000"/>
	</joint>
	<joint name="left_shoulder_roll_joint" type="continuous">
		<parent link="left_shoulder_pitch_link"/>
		<child link="link0_18"/>
		<dynamics damping="1.0" friction="0.0001"/>
		<origin rpy="0.00000 -0.00000 0.00000" xyz="-0.01800 -0.00000 -0.05200"/>
		<axis xyz="-0.00000 0.00000 -1.00000"/>
	</joint>
	<joint name="jointfix_10_18" type="fixed">
		<parent link="link0_18"/>
		<child link="left_shoulder_roll_link"/>
		<dynamics damping="1.0" friction="0.0001"/>
		<origin rpy="0.00000 -0.00000 0.00000" xyz="0.00000 0.00000 0.00000"/>
		<axis xyz="0.00000 0.00000 0.00000"/>
	</joint>
	<joint name="left_shoulder_yaw_joint" type="continuous">
		<parent link="left_shoulder_roll_link"/>
		<child link="link0_20"/>
		<dynamics damping="1.0" friction="0.0001"/>
		<origin rpy="0.00000 -0.00000 0.00000" xyz="-0.00000 -0.13400 0.01800"/>
		<axis xyz="-0.00000 -0.00000 1.00000"/>
	</joint>
	<joint name="jointfix_9_20" type="fixed">
		<parent link="link0_20"/>
		<child link="left_shoulder_yaw_link"/>
		<dynamics damping="1.0" friction="0.0001"/>
		<origin rpy="0.00000 -0.00000 0.00000" xyz="0.00000 0.00000 -0.00000"/>
		<axis xyz="0.00000 0.00000 0.00000"/>
	</joint>
	<joint name="left_elbow_joint" type="continuous">
		<parent link="left_shoulder_yaw_link"/>
		<child link="link0_22"/>
		<dynamics damping="1.0" friction="0.0001"/>
		<origin rpy="0.00000 -0.00000 0.00000" xyz="-0.02650 -0.00000 0.16950"/>
		<axis xyz="0.00000 -0.00000 1.00000"/>
	</joint>
	<joint name="jointfix_8_22" type="fixed">
		<parent link="link0_22"/>
		<child link="left_elbow_link"/>
		<dynamics damping="1.0" friction="0.0001"/>
		<origin rpy="0.00000 -0.00000 0.00000" xyz="-0.00000 0.00000 -0.04450"/>
		<axis xyz="0.00000 0.00000 0.00000"/>
	</joint>
	<joint name="jointfix_7_21" type="fixed">
		<parent link="left_elbow_link"/>
		<child link="left_hand_link"/>
		<dynamics damping="1.0" friction="0.0001"/>
		<origin rpy="0.00000 -0.00000 0.00000" xyz="0.00000 -0.23800 0.02650"/>
		<axis xyz="0.00000 0.00000 0.00000"/>
	</joint>
	<joint name="axle_1_joint" type="continuous">
		<parent link="base_link"/>
		<child link="link0_25"/>
		<dynamics damping="1.0" friction="0.0001"/>
		<origin rpy="0.00000 -0.00000 0.00000" xyz="0.11575 0.00000 0.13715"/>
		<axis xyz="0.00000 -0.00000 -1.00000"/>
	</joint>
	<joint name="jointfix_25_25" type="fixed">
		<parent link="link0_25"/>
		<child link="axle_1_link"/>
		<dynamics damping="1.0" friction="0.0001"/>
		<origin rpy="0.00000 -0.00000 0.00000" xyz="0.00000 -0.00000 -0.01970"/>
		<axis xyz="0.00000 0.00000 0.00000"/>
	</joint>
	<joint name="fat_roller_1_1_joint" type="continuous">
		<parent link="axle_1_link"/>
		<child link="link0_27"/>
		<dynamics damping="1.0" friction="0.0001"/>
		<origin rpy="0.00000 -0.00000 0.00000" xyz="0.03333 -0.00991 -0.00150"/>
		<axis xyz="1.00000 -0.00000 0.00000"/>
	</joint>
	<joint name="jointfix_13_27" type="fixed">
		<parent link="link0_27"/>
		<child link="fat_roller_1_1_link"/>
		<dynamics damping="1.0" friction="0.0001"/>
		<origin rpy="0.00000 -0.00000 0.00000" xyz="0.00384 -0.00000 0.00000"/>
		<axis xyz="0.00000 0.00000 0.00000"/>
	</joint>
	<joint name="fat_roller_1_2_joint" type="continuous">
		<parent link="axle_1_link"/>
		<child link="link0_29"/>
		<dynamics damping="1.0" friction="0.0001"/>
		<origin rpy="0.00000 -0.00000 0.00000" xyz="0.00616 -0.03714 -0.00150"/>
		<axis xyz="1.00000 0.00000 -0.00000"/>
	</joint>
	<joint name="jointfix_14_29" type="fixed">
		<parent link="link0_29"/>
		<child link="fat_roller_1_2_link"/>
		<dynamics damping="1.0" friction="0.0001"/>
		<origin rpy="0.00000 -0.00000 0.00000" xyz="0.00384 0.00000 0.00000"/>
		<axis xyz="0.00000 0.00000 0.00000"/>
	</joint>
	<joint name="fat_roller_1_3_joint" type="continuous">
		<parent link="axle_1_link"/>
		<child link="link0_31"/>
		<dynamics damping="1.0" friction="0.0001"/>
		<origin rpy="0.00000 -0.00000 0.00000" xyz="-0.03100 -0.02723 -0.00150"/>
		<axis xyz="1.00000 -0.00000 -0.00000"/>
	</joint>
	<joint name="jointfix_15_31" type="fixed">
		<parent link="link0_31"/>
		<child link="fat_roller_1_3_link"/>
		<dynamics damping="1.0" friction="0.0001"/>
		<origin rpy="0.00000 -0.00000 0.00000" xyz="0.00384 -0.00000 -0.00000"/>
		<axis xyz="0.00000 0.00000 0.00000"/>
	</joint>
	<joint name="fat_roller_1_4_joint" type="continuous">
		<parent link="axle_1_link"/>
		<child link="link0_33"/>
		<dynamics damping="1.0" friction="0.0001"/>
		<origin rpy="0.00000 -0.00000 0.00000" xyz="-0.04101 0.00991 -0.00150"/>
		<axis xyz="1.00000 -0.00000 -0.00000"/>
	</joint>
	<joint name="jointfix_16_33" type="fixed">
		<parent link="link0_33"/>
		<child link="fat_roller_1_4_link"/>
		<dynamics damping="1.0" friction="0.0001"/>
		<origin rpy="0.00000 -0.00000 0.00000" xyz="0.00384 -0.00000 -0.00000"/>
		<axis xyz="0.00000 0.00000 0.00000"/>
	</joint>
	<joint name="fat_roller_1_5_joint" type="continuous">
		<parent link="axle_1_link"/>
		<child link="link0_35"/>
		<dynamics damping="1.0" friction="0.0001"/>
		<origin rpy="0.00000 -0.00000 0.00000" xyz="-0.01384 0.03714 -0.00150"/>
		<axis xyz="1.00000 0.00000 0.00000"/>
	</joint>
	<joint name="jointfix_17_35" type="fixed">
		<parent link="link0_35"/>
		<child link="fat_roller_1_5_link"/>
		<dynamics damping="1.0" friction="0.0001"/>
		<origin rpy="0.00000 -0.00000 0.00000" xyz="0.00384 0.00000 0.00000"/>
		<axis xyz="0.00000 0.00000 0.00000"/>
	</joint>
	<joint name="fat_roller_1_6_joint" type="continuous">
		<parent link="axle_1_link"/>
		<child link="link0_37"/>
		<dynamics damping="1.0" friction="0.0001"/>
		<origin rpy="0.00000 -0.00000 0.00000" xyz="0.02332 0.02723 -0.00150"/>
		<axis xyz="1.00000 -0.00000 0.00000"/>
	</joint>
	<joint name="jointfix_18_37" type="fixed">
		<parent link="link0_37"/>
		<child link="fat_roller_1_6_link"/>
		<dynamics damping="1.0" friction="0.0001"/>
		<origin rpy="0.00000 -0.00000 0.00000" xyz="0.00384 -0.00000 0.00000"/>
		<axis xyz="0.00000 0.00000 0.00000"/>
	</joint>
	<joint name="thin_roller_1_1_joint" type="continuous">
		<parent link="axle_1_link"/>
		<child link="link0_39"/>
		<dynamics damping="1.0" friction="0.0001"/>
		<origin rpy="0.00000 -0.00000 0.00000" xyz="0.02857 0.01112 -0.00150"/>
		<axis xyz="-1.00000 -0.00000 -0.00000"/>
	</joint>
	<joint name="jointfix_19_39" type="fixed">
		<parent link="link0_39"/>
		<child link="thin_roller_1_1_link"/>
		<dynamics damping="1.0" friction="0.0001"/>
		<origin rpy="0.00000 -0.00000 0.00000" xyz="0.01288 0.00000 0.00000"/>
		<axis xyz="0.00000 0.00000 0.00000"/>
	</joint>
	<joint name="thin_roller_1_2_joint" type="continuous">
		<parent link="axle_1_link"/>
		<child link="link0_41"/>
		<dynamics damping="1.0" friction="0.0001"/>
		<origin rpy="0.00000 -0.00000 0.00000" xyz="0.01748 -0.03034 -0.00150"/>
		<axis xyz="-1.00000 -0.00000 0.00000"/>
	</joint>
	<joint name="jointfix_20_41" type="fixed">
		<parent link="link0_41"/>
		<child link="thin_roller_1_2_link"/>
		<dynamics damping="1.0" friction="0.0001"/>
		<origin rpy="0.00000 -0.00000 0.00000" xyz="0.01288 0.00000 0.00000"/>
		<axis xyz="0.00000 0.00000 0.00000"/>
	</joint>
	<joint name="thin_roller_1_3_joint" type="continuous">
		<parent link="axle_1_link"/>
		<child link="link0_43"/>
		<dynamics damping="1.0" friction="0.0001"/>
		<origin rpy="0.00000 -0.00000 0.00000" xyz="-0.02397 -0.04146 -0.00150"/>
		<axis xyz="-1.00000 -0.00000 0.00000"/>
	</joint>
	<joint name="jointfix_21_43" type="fixed">
		<parent link="link0_43"/>
		<child link="thin_roller_1_3_link"/>
		<dynamics damping="1.0" friction="0.0001"/>
		<origin rpy="0.00000 -0.00000 0.00000" xyz="0.01288 0.00000 0.00000"/>
		<axis xyz="0.00000 0.00000 0.00000"/>
	</joint>
	<joint name="thin_roller_1_4_joint" type="continuous">
		<parent link="axle_1_link"/>
		<child link="link0_45"/>
		<dynamics damping="1.0" friction="0.0001"/>
		<origin rpy="0.00000 -0.00000 0.00000" xyz="-0.05433 -0.01112 -0.00150"/>
		<axis xyz="-1.00000 -0.00000 0.00000"/>
	</joint>
	<joint name="jointfix_22_45" type="fixed">
		<parent link="link0_45"/>
		<child link="thin_roller_1_4_link"/>
		<dynamics damping="1.0" friction="0.0001"/>
		<origin rpy="0.00000 -0.00000 0.00000" xyz="0.01288 -0.00000 0.00000"/>
		<axis xyz="0.00000 0.00000 0.00000"/>
	</joint>
	<joint name="thin_roller_1_5_joint" type="continuous">
		<parent link="axle_1_link"/>
		<child link="link0_47"/>
		<dynamics damping="1.0" friction="0.0001"/>
		<origin rpy="0.00000 -0.00000 0.00000" xyz="-0.04323 0.03034 -0.00150"/>
		<axis xyz="-1.00000 -0.00000 -0.00000"/>
	</joint>
	<joint name="jointfix_23_47" type="fixed">
		<parent link="link0_47"/>
		<child link="thin_roller_1_5_link"/>
		<dynamics damping="1.0" friction="0.0001"/>
		<origin rpy="0.00000 -0.00000 0.00000" xyz="0.01288 0.00000 -0.00000"/>
		<axis xyz="0.00000 0.00000 0.00000"/>
	</joint>
	<joint name="thin_roller_1_6_joint" type="continuous">
		<parent link="axle_1_link"/>
		<child link="link0_49"/>
		<dynamics damping="1.0" friction="0.0001"/>
		<origin rpy="0.00000 -0.00000 0.00000" xyz="-0.00178 0.04146 -0.00150"/>
		<axis xyz="-1.00000 -0.00000 -0.00000"/>
	</joint>
	<joint name="jointfix_24_49" type="fixed">
		<parent link="link0_49"/>
		<child link="thin_roller_1_6_link"/>
		<dynamics damping="1.0" friction="0.0001"/>
		<origin rpy="0.00000 -0.00000 0.00000" xyz="0.01288 0.00000 -0.00000"/>
		<axis xyz="0.00000 0.00000 0.00000"/>
	</joint>
	<joint name="axle_2_joint" type="continuous">
		<parent link="base_link"/>
		<child link="link0_51"/>
		<dynamics damping="1.0" friction="0.0001"/>
		<origin rpy="0.00000 -0.00000 0.00000" xyz="-0.05788 0.10025 0.13715"/>
		<axis xyz="0.00000 -0.00000 -1.00000"/>
	</joint>
	<joint name="jointfix_38_51" type="fixed">
		<parent link="link0_51"/>
		<child link="axle_2_link"/>
		<dynamics damping="1.0" friction="0.0001"/>
		<origin rpy="0.00000 -0.00000 0.00000" xyz="0.00000 -0.00000 -0.01970"/>
		<axis xyz="0.00000 0.00000 0.00000"/>
	</joint>
	<joint name="fat_roller_2_1_joint" type="continuous">
		<parent link="axle_2_link"/>
		<child link="link0_53"/>
		<dynamics damping="1.0" friction="0.0001"/>
		<origin rpy="0.00000 -0.00000 0.00000" xyz="-0.01384 0.03714 -0.00150"/>
		<axis xyz="1.00000 0.00000 0.00000"/>
	</joint>
	<joint name="jointfix_26_53" type="fixed">
		<parent link="link0_53"/>
		<child link="fat_roller_2_1_link"/>
		<dynamics damping="1.0" friction="0.0001"/>
		<origin rpy="0.00000 -0.00000 0.00000" xyz="0.00384 -0.00000 -0.00000"/>
		<axis xyz="0.00000 0.00000 0.00000"/>
	</joint>
	<joint name="fat_roller_2_2_joint" type="continuous">
		<parent link="axle_2_link"/>
		<child link="link0_55"/>
		<dynamics damping="1.0" friction="0.0001"/>
		<origin rpy="0.00000 -0.00000 0.00000" xyz="0.02332 0.02723 -0.00150"/>
		<axis xyz="1.00000 0.00000 0.00000"/>
	</joint>
	<joint name="jointfix_27_55" type="fixed">
		<parent link="link0_55"/>
		<child link="fat_roller_2_2_link"/>
		<dynamics damping="1.0" friction="0.0001"/>
		<origin rpy="0.00000 -0.00000 0.00000" xyz="0.00384 0.00000 -0.00000"/>
		<axis xyz="0.00000 0.00000 0.00000"/>
	</joint>
	<joint name="fat_roller_2_3_joint" type="continuous">
		<parent link="axle_2_link"/>
		<child link="link0_57"/>
		<dynamics damping="1.0" friction="0.0001"/>
		<origin rpy="0.00000 -0.00000 0.00000" xyz="0.03333 -0.00991 -0.00150"/>
		<axis xyz="1.00000 -0.00000 -0.00000"/>
	</joint>
	<joint name="jointfix_28_57" type="fixed">
		<parent link="link0_57"/>
		<child link="fat_roller_2_3_link"/>
		<dynamics damping="1.0" friction="0.0001"/>
		<origin rpy="0.00000 -0.00000 0.00000" xyz="0.00384 -0.00000 0.00000"/>
		<axis xyz="0.00000 0.00000 0.00000"/>
	</joint>
	<joint name="fat_roller_2_4_joint" type="continuous">
		<parent link="axle_2_link"/>
		<child link="link0_59"/>
		<dynamics damping="1.0" friction="0.0001"/>
		<origin rpy="0.00000 -0.00000 0.00000" xyz="0.00616 -0.03714 -0.00150"/>
		<axis xyz="1.00000 0.00000 -0.00000"/>
	</joint>
	<joint name="jointfix_29_59" type="fixed">
		<parent link="link0_59"/>
		<child link="fat_roller_2_4_link"/>
		<dynamics damping="1.0" friction="0.0001"/>
		<origin rpy="0.00000 -0.00000 0.00000" xyz="0.00384 -0.00000 -0.00000"/>
		<axis xyz="0.00000 0.00000 0.00000"/>
	</joint>
	<joint name="fat_roller_2_5_joint" type="continuous">
		<parent link="axle_2_link"/>
		<child link="link0_61"/>
		<dynamics damping="1.0" friction="0.0001"/>
		<origin rpy="0.00000 -0.00000 0.00000" xyz="-0.03100 -0.02723 -0.00150"/>
		<axis xyz="1.00000 0.00000 -0.00000"/>
	</joint>
	<joint name="jointfix_30_61" type="fixed">
		<parent link="link0_61"/>
		<child link="fat_roller_2_5_link"/>
		<dynamics damping="1.0" friction="0.0001"/>
		<origin rpy="0.00000 -0.00000 0.00000" xyz="0.00384 -0.00000 -0.00000"/>
		<axis xyz="0.00000 0.00000 0.00000"/>
	</joint>
	<joint name="fat_roller_2_6_joint" type="continuous">
		<parent link="axle_2_link"/>
		<child link="link0_63"/>
		<dynamics damping="1.0" friction="0.0001"/>
		<origin rpy="0.00000 -0.00000 0.00000" xyz="-0.04101 0.00991 -0.00150"/>
		<axis xyz="1.00000 -0.00000 0.00000"/>
	</joint>
	<joint name="jointfix_31_63" type="fixed">
		<parent link="link0_63"/>
		<child link="fat_roller_2_6_link"/>
		<dynamics damping="1.0" friction="0.0001"/>
		<origin rpy="0.00000 -0.00000 0.00000" xyz="0.00384 -0.00000 -0.00000"/>
		<axis xyz="0.00000 0.00000 0.00000"/>
	</joint>
	<joint name="thin_roller_2_1_joint" type="continuous">
		<parent link="axle_2_link"/>
		<child link="link0_65"/>
		<dynamics damping="1.0" friction="0.0001"/>
		<origin rpy="0.00000 -0.00000 0.00000" xyz="-0.04323 0.03034 -0.00150"/>
		<axis xyz="-1.00000 -0.00000 -0.00000"/>
	</joint>
	<joint name="jointfix_32_65" type="fixed">
		<parent link="link0_65"/>
		<child link="thin_roller_2_1_link"/>
		<dynamics damping="1.0" friction="0.0001"/>
		<origin rpy="0.00000 -0.00000 0.00000" xyz="0.01288 -0.00000 -0.00000"/>
		<axis xyz="0.00000 0.00000 0.00000"/>
	</joint>
	<joint name="thin_roller_2_2_joint" type="continuous">
		<parent link="axle_2_link"/>
		<child link="link0_67"/>
		<dynamics damping="1.0" friction="0.0001"/>
		<origin rpy="0.00000 -0.00000 0.00000" xyz="-0.00178 0.04146 -0.00150"/>
		<axis xyz="-1.00000 -0.00000 -0.00000"/>
	</joint>
	<joint name="jointfix_33_67" type="fixed">
		<parent link="link0_67"/>
		<child link="thin_roller_2_2_link"/>
		<dynamics damping="1.0" friction="0.0001"/>
		<origin rpy="0.00000 -0.00000 0.00000" xyz="0.01288 -0.00000 -0.00000"/>
		<axis xyz="0.00000 0.00000 0.00000"/>
	</joint>
	<joint name="thin_roller_2_3_joint" type="continuous">
		<parent link="axle_2_link"/>
		<child link="link0_69"/>
		<dynamics damping="1.0" friction="0.0001"/>
		<origin rpy="0.00000 -0.00000 0.00000" xyz="0.02857 0.01112 -0.00150"/>
		<axis xyz="-1.00000 -0.00000 0.00000"/>
	</joint>
	<joint name="jointfix_34_69" type="fixed">
		<parent link="link0_69"/>
		<child link="thin_roller_2_3_link"/>
		<dynamics damping="1.0" friction="0.0001"/>
		<origin rpy="0.00000 -0.00000 0.00000" xyz="0.01288 0.00000 0.00000"/>
		<axis xyz="0.00000 0.00000 0.00000"/>
	</joint>
	<joint name="thin_roller_2_4_joint" type="continuous">
		<parent link="axle_2_link"/>
		<child link="link0_71"/>
		<dynamics damping="1.0" friction="0.0001"/>
		<origin rpy="0.00000 -0.00000 0.00000" xyz="0.01748 -0.03034 -0.00150"/>
		<axis xyz="-1.00000 -0.00000 0.00000"/>
	</joint>
	<joint name="jointfix_35_71" type="fixed">
		<parent link="link0_71"/>
		<child link="thin_roller_2_4_link"/>
		<dynamics damping="1.0" friction="0.0001"/>
		<origin rpy="0.00000 -0.00000 0.00000" xyz="0.01288 0.00000 0.00000"/>
		<axis xyz="0.00000 0.00000 0.00000"/>
	</joint>
	<joint name="thin_roller_2_5_joint" type="continuous">
		<parent link="axle_2_link"/>
		<child link="link0_73"/>
		<dynamics damping="1.0" friction="0.0001"/>
		<origin rpy="0.00000 -0.00000 0.00000" xyz="-0.02397 -0.04146 -0.00150"/>
		<axis xyz="-1.00000 -0.00000 0.00000"/>
	</joint>
	<joint name="jointfix_36_73" type="fixed">
		<parent link="link0_73"/>
		<child link="thin_roller_2_5_link"/>
		<dynamics damping="1.0" friction="0.0001"/>
		<origin rpy="0.00000 -0.00000 0.00000" xyz="0.01288 0.00000 0.00000"/>
		<axis xyz="0.00000 0.00000 0.00000"/>
	</joint>
	<joint name="thin_roller_2_6_joint" type="continuous">
		<parent link="axle_2_link"/>
		<child link="link0_75"/>
		<dynamics damping="1.0" friction="0.0001"/>
		<origin rpy="0.00000 -0.00000 0.00000" xyz="-0.05433 -0.01112 -0.00150"/>
		<axis xyz="-1.00000 -0.00000 -0.00000"/>
	</joint>
	<joint name="jointfix_37_75" type="fixed">
		<parent link="link0_75"/>
		<child link="thin_roller_2_6_link"/>
		<dynamics damping="1.0" friction="0.0001"/>
		<origin rpy="0.00000 -0.00000 0.00000" xyz="0.01288 0.00000 -0.00000"/>
		<axis xyz="0.00000 0.00000 0.00000"/>
	</joint>
	<joint name="axle_3_joint" type="continuous">
		<parent link="base_link"/>
		<child link="link0_77"/>
		<dynamics damping="1.0" friction="0.0001"/>
		<origin rpy="0.00000 -0.00000 0.00000" xyz="-0.05788 -0.10025 0.13700"/>
		<axis xyz="0.00000 0.00000 -1.00000"/>
	</joint>
	<joint name="jointfix_51_77" type="fixed">
		<parent link="link0_77"/>
		<child link="axle_3_link"/>
		<dynamics damping="1.0" friction="0.0001"/>
		<origin rpy="0.00000 -0.00000 0.00000" xyz="0.00000 0.00000 -0.01970"/>
		<axis xyz="0.00000 0.00000 0.00000"/>
	</joint>
	<joint name="fat_roller_3_1_joint" type="continuous">
		<parent link="axle_3_link"/>
		<child link="link0_79"/>
		<dynamics damping="1.0" friction="0.0001"/>
		<origin rpy="0.00000 -0.00000 0.00000" xyz="0.00616 -0.03714 -0.00150"/>
		<axis xyz="1.00000 0.00000 -0.00000"/>
	</joint>
	<joint name="jointfix_39_79" type="fixed">
		<parent link="link0_79"/>
		<child link="fat_roller_3_1_link"/>
		<dynamics damping="1.0" friction="0.0001"/>
		<origin rpy="0.00000 -0.00000 0.00000" xyz="0.00384 -0.00000 0.00000"/>
		<axis xyz="0.00000 0.00000 0.00000"/>
	</joint>
	<joint name="fat_roller_3_2_joint" type="continuous">
		<parent link="axle_3_link"/>
		<child link="link0_81"/>
		<dynamics damping="1.0" friction="0.0001"/>
		<origin rpy="0.00000 -0.00000 0.00000" xyz="-0.03100 -0.02723 -0.00150"/>
		<axis xyz="1.00000 -0.00000 0.00000"/>
	</joint>
	<joint name="jointfix_40_81" type="fixed">
		<parent link="link0_81"/>
		<child link="fat_roller_3_2_link"/>
		<dynamics damping="1.0" friction="0.0001"/>
		<origin rpy="0.00000 -0.00000 0.00000" xyz="0.00384 0.00000 0.00000"/>
		<axis xyz="0.00000 0.00000 0.00000"/>
	</joint>
	<joint name="fat_roller_3_3_joint" type="continuous">
		<parent link="axle_3_link"/>
		<child link="link0_83"/>
		<dynamics damping="1.0" friction="0.0001"/>
		<origin rpy="0.00000 -0.00000 0.00000" xyz="-0.04101 0.00991 -0.00150"/>
		<axis xyz="1.00000 -0.00000 0.00000"/>
	</joint>
	<joint name="jointfix_41_83" type="fixed">
		<parent link="link0_83"/>
		<child link="fat_roller_3_3_link"/>
		<dynamics damping="1.0" friction="0.0001"/>
		<origin rpy="0.00000 -0.00000 0.00000" xyz="0.00384 -0.00000 0.00000"/>
		<axis xyz="0.00000 0.00000 0.00000"/>
	</joint>
	<joint name="fat_roller_3_4_joint" type="continuous">
		<parent link="axle_3_link"/>
		<child link="link0_85"/>
		<dynamics damping="1.0" friction="0.0001"/>
		<origin rpy="0.00000 -0.00000 0.00000" xyz="-0.01384 0.03714 -0.00150"/>
		<axis xyz="1.00000 0.00000 0.00000"/>
	</joint>
	<joint name="jointfix_42_85" type="fixed">
		<parent link="link0_85"/>
		<child link="fat_roller_3_4_link"/>
		<dynamics damping="1.0" friction="0.0001"/>
		<origin rpy="0.00000 -0.00000 0.00000" xyz="0.00384 0.00000 -0.00000"/>
		<axis xyz="0.00000 0.00000 0.00000"/>
	</joint>
	<joint name="fat_roller_3_5_joint" type="continuous">
		<parent link="axle_3_link"/>
		<child link="link0_87"/>
		<dynamics damping="1.0" friction="0.0001"/>
		<origin rpy="0.00000 -0.00000 0.00000" xyz="0.02332 0.02723 -0.00150"/>
		<axis xyz="1.00000 -0.00000 -0.00000"/>
	</joint>
	<joint name="jointfix_43_87" type="fixed">
		<parent link="link0_87"/>
		<child link="fat_roller_3_5_link"/>
		<dynamics damping="1.0" friction="0.0001"/>
		<origin rpy="0.00000 -0.00000 0.00000" xyz="0.00384 0.00000 -0.00000"/>
		<axis xyz="0.00000 0.00000 0.00000"/>
	</joint>
	<joint name="fat_roller_3_6_joint" type="continuous">
		<parent link="axle_3_link"/>
		<child link="link0_89"/>
		<dynamics damping="1.0" friction="0.0001"/>
		<origin rpy="0.00000 -0.00000 0.00000" xyz="0.03333 -0.00991 -0.00150"/>
		<axis xyz="1.00000 -0.00000 -0.00000"/>
	</joint>
	<joint name="jointfix_44_89" type="fixed">
		<parent link="link0_89"/>
		<child link="fat_roller_3_6_link"/>
		<dynamics damping="1.0" friction="0.0001"/>
		<origin rpy="0.00000 -0.00000 0.00000" xyz="0.00384 -0.00000 -0.00000"/>
		<axis xyz="0.00000 0.00000 0.00000"/>
	</joint>
	<joint name="thin_roller_3_1_joint" type="continuous">
		<parent link="axle_3_link"/>
		<child link="link0_91"/>
		<dynamics damping="1.0" friction="0.0001"/>
		<origin rpy="0.00000 -0.00000 0.00000" xyz="-0.02397 -0.04146 -0.00150"/>
		<axis xyz="-1.00000 -0.00000 -0.00000"/>
	</joint>
	<joint name="jointfix_45_91" type="fixed">
		<parent link="link0_91"/>
		<child link="thin_roller_3_1_link"/>
		<dynamics damping="1.0" friction="0.0001"/>
		<origin rpy="0.00000 -0.00000 0.00000" xyz="0.01288 0.00000 0.00000"/>
		<axis xyz="0.00000 0.00000 0.00000"/>
	</joint>
	<joint name="thin_roller_3_2_joint" type="continuous">
		<parent link="axle_3_link"/>
		<child link="link0_93"/>
		<dynamics damping="1.0" friction="0.0001"/>
		<origin rpy="0.00000 -0.00000 0.00000" xyz="-0.05433 -0.01112 -0.00150"/>
		<axis xyz="-1.00000 0.00000 0.00000"/>
	</joint>
	<joint name="jointfix_46_93" type="fixed">
		<parent link="link0_93"/>
		<child link="thin_roller_3_2_link"/>
		<dynamics damping="1.0" friction="0.0001"/>
		<origin rpy="0.00000 -0.00000 0.00000" xyz="0.01288 0.00000 0.00000"/>
		<axis xyz="0.00000 0.00000 0.00000"/>
	</joint>
	<joint name="thin_roller_3_3_joint" type="continuous">
		<parent link="axle_3_link"/>
		<child link="link0_95"/>
		<dynamics damping="1.0" friction="0.0001"/>
		<origin rpy="0.00000 -0.00000 0.00000" xyz="-0.04323 0.03034 -0.00150"/>
		<axis xyz="-1.00000 0.00000 -0.00000"/>
	</joint>
	<joint name="jointfix_47_95" type="fixed">
		<parent link="link0_95"/>
		<child link="thin_roller_3_3_link"/>
		<dynamics damping="1.0" friction="0.0001"/>
		<origin rpy="0.00000 -0.00000 0.00000" xyz="0.01288 -0.00000 -0.00000"/>
		<axis xyz="0.00000 0.00000 0.00000"/>
	</joint>
	<joint name="thin_roller_3_4_joint" type="continuous">
		<parent link="axle_3_link"/>
		<child link="link0_97"/>
		<dynamics damping="1.0" friction="0.0001"/>
		<origin rpy="0.00000 -0.00000 0.00000" xyz="-0.00178 0.04146 -0.00150"/>
		<axis xyz="-1.00000 -0.00000 0.00000"/>
	</joint>
	<joint name="jointfix_48_97" type="fixed">
		<parent link="link0_97"/>
		<child link="thin_roller_3_4_link"/>
		<dynamics damping="1.0" friction="0.0001"/>
		<origin rpy="0.00000 -0.00000 0.00000" xyz="0.01288 -0.00000 0.00000"/>
		<axis xyz="0.00000 0.00000 0.00000"/>
	</joint>
	<joint name="thin_roller_3_5_joint" type="continuous">
		<parent link="axle_3_link"/>
		<child link="link0_99"/>
		<dynamics damping="1.0" friction="0.0001"/>
		<origin rpy="0.00000 -0.00000 0.00000" xyz="0.02857 0.01112 -0.00150"/>
		<axis xyz="-1.00000 0.00000 -0.00000"/>
	</joint>
	<joint name="jointfix_49_99" type="fixed">
		<parent link="link0_99"/>
		<child link="thin_roller_3_5_link"/>
		<dynamics damping="1.0" friction="0.0001"/>
		<origin rpy="0.00000 -0.00000 0.00000" xyz="0.01288 0.00000 -0.00000"/>
		<axis xyz="0.00000 0.00000 0.00000"/>
	</joint>
	<joint name="thin_roller_3_6_joint" type="continuous">
		<parent link="axle_3_link"/>
		<child link="link0_101"/>
		<dynamics damping="1.0" friction="0.0001"/>
		<origin rpy="0.00000 -0.00000 0.00000" xyz="0.01748 -0.03034 -0.00150"/>
		<axis xyz="-1.00000 0.00000 0.00000"/>
	</joint>
	<joint name="jointfix_50_101" type="fixed">
		<parent link="link0_101"/>
		<child link="thin_roller_3_6_link"/>
		<dynamics damping="1.0" friction="0.0001"/>
		<origin rpy="0.00000 -0.00000 0.00000" xyz="0.01288 0.00000 -0.00000"/>
		<axis xyz="0.00000 0.00000 0.00000"/>
	</joint>
</robot>
